2024-06-02 20:20:46,713 INFO    MainThread:14078 [wandb_setup.py:_flush():76] Current SDK version is 0.16.5
2024-06-02 20:20:46,713 INFO    MainThread:14078 [wandb_setup.py:_flush():76] Configure stats pid to 14078
2024-06-02 20:20:46,713 INFO    MainThread:14078 [wandb_setup.py:_flush():76] Loading settings from /home/zihao/.config/wandb/settings
2024-06-02 20:20:46,713 INFO    MainThread:14078 [wandb_setup.py:_flush():76] Loading settings from /home/zihao/Multi-GNN/wandb/settings
2024-06-02 20:20:46,713 INFO    MainThread:14078 [wandb_setup.py:_flush():76] Loading settings from environment variables: {}
2024-06-02 20:20:46,713 INFO    MainThread:14078 [wandb_setup.py:_flush():76] Applying setup settings: {'_disable_service': False}
2024-06-02 20:20:46,713 INFO    MainThread:14078 [wandb_setup.py:_flush():76] Inferring run settings from compute environment: {'program_relpath': 'main.py', 'program_abspath': '/home/zihao/Multi-GNN/main.py', 'program': '/home/zihao/Multi-GNN/main.py'}
2024-06-02 20:20:46,713 INFO    MainThread:14078 [wandb_setup.py:_flush():76] Applying login settings: {}
2024-06-02 20:20:46,713 INFO    MainThread:14078 [wandb_setup.py:_flush():76] Applying login settings: {'mode': 'offline'}
2024-06-02 20:20:46,714 INFO    MainThread:14078 [wandb_init.py:_log_setup():527] Logging user logs to /home/zihao/Multi-GNN/wandb/run-20240602_202046-dvlzcegl/logs/debug.log
2024-06-02 20:20:46,714 INFO    MainThread:14078 [wandb_init.py:_log_setup():528] Logging internal logs to /home/zihao/Multi-GNN/wandb/run-20240602_202046-dvlzcegl/logs/debug-internal.log
2024-06-02 20:20:46,714 INFO    MainThread:14078 [wandb_init.py:init():567] calling init triggers
2024-06-02 20:20:46,714 INFO    MainThread:14078 [wandb_init.py:init():574] wandb.init called with sweep_config: {}
config: {'epochs': 100, 'batch_size': 8192, 'model': 'pna', 'data': '', 'num_neighbors': [100, 100], 'lr': 0.0006116418195373612, 'n_hidden': 20, 'n_gnn_layers': 2, 'loss': 'ce', 'w_ce1': 1.0003967674742307, 'w_ce2': 7.077633468006714, 'dropout': 0.08340440094051481, 'final_dropout': 0.28812979737686323, 'n_heads': None}
2024-06-02 20:20:46,714 INFO    MainThread:14078 [wandb_init.py:init():617] starting backend
2024-06-02 20:20:46,714 INFO    MainThread:14078 [wandb_init.py:init():621] setting up manager
2024-06-02 20:20:46,718 INFO    MainThread:14078 [backend.py:_multiprocessing_setup():105] multiprocessing start_methods=fork,spawn,forkserver, using: spawn
2024-06-02 20:20:46,721 INFO    MainThread:14078 [wandb_init.py:init():629] backend started and connected
2024-06-02 20:20:46,730 INFO    MainThread:14078 [wandb_init.py:init():721] updated telemetry
2024-06-02 20:20:46,796 INFO    MainThread:14078 [wandb_init.py:init():754] communicating run to backend with 90.0 second timeout
2024-06-02 20:20:47,241 ERROR   MainThread:14078 [wandb_init.py:init():780] encountered error: The API key you provided is either invalid or missing.  If the `WANDB_API_KEY` environment variable is set, make sure it is correct. Otherwise, to resolve this issue, you may try running the 'wandb login --relogin' command. If you are using a local server, make sure that you're using the correct hostname. If you're not sure, you can try logging in again using the 'wandb login --relogin --host [hostname]' command.(Error 401: Unauthorized)
2024-06-02 20:20:47,316 ERROR   MainThread:14078 [wandb_init.py:init():1205] The API key you provided is either invalid or missing.  If the `WANDB_API_KEY` environment variable is set, make sure it is correct. Otherwise, to resolve this issue, you may try running the 'wandb login --relogin' command. If you are using a local server, make sure that you're using the correct hostname. If you're not sure, you can try logging in again using the 'wandb login --relogin --host [hostname]' command.(Error 401: Unauthorized)
Traceback (most recent call last):
  File "/home/zihao/anaconda3/envs/multignn/lib/python3.9/site-packages/wandb/sdk/wandb_init.py", line 1187, in init
    run = wi.init()
  File "/home/zihao/anaconda3/envs/multignn/lib/python3.9/site-packages/wandb/sdk/wandb_init.py", line 786, in init
    raise error
wandb.errors.AuthenticationError: The API key you provided is either invalid or missing.  If the `WANDB_API_KEY` environment variable is set, make sure it is correct. Otherwise, to resolve this issue, you may try running the 'wandb login --relogin' command. If you are using a local server, make sure that you're using the correct hostname. If you're not sure, you can try logging in again using the 'wandb login --relogin --host [hostname]' command.(Error 401: Unauthorized)
